<robot name="thor_robot" version="1.0">
  <joint name="junta1" type="revolute">
    <limit lower="-3.140000" upper="3.140000" effort="0.000000" velocity="0.000000"/>
    <origin rpy="0.000000 0.000000 0.000000" xyz="0.000000 0.000000 0.098000"/>
    <parent link="base.000"/>
    <child link="Art1_3d_link"/>
    <axis xyz="0.000000 0.000000 1.000000"/>
  </joint>
  <joint name="junta2" type="revolute">
    <limit lower="-3.140000" upper="3.140000" effort="0.000000" velocity="0.000000"/>
    <origin rpy="-1.570796 0.000000 0.000000" xyz="0.000000 -0.000000 0.098000"/>
    <parent link="Art1_3d_link"/>
    <child link="art2_3d_link"/>
    <axis xyz="0.000000 0.000000 1.000000"/>
  </joint>
  <joint name="junta3" type="revolute">
    <limit lower="-3.140000" upper="3.140000" effort="0.000000" velocity="0.000000"/>
    <origin rpy="-0.000000 0.000000 0.000000" xyz="0.000000 -0.160000 -0.000000"/>
    <parent link="art2_3d_link"/>
    <child link="art3_3d_link"/>
    <axis xyz="0.000000 0.000000 1.000000"/>
  </joint>
  <joint name="junta4" type="revolute">
    <limit lower="-3.140000" upper="3.140000" effort="0.000000" velocity="0.000000"/>
    <origin rpy="1.570796 0.000000 0.000000" xyz="0.000000 -0.088500 -0.000000"/>
    <parent link="art3_3d_link"/>
    <child link="art4_3d_link"/>
    <axis xyz="0.000000 0.000000 1.000000"/>
  </joint>
  <joint name="junta5" type="revolute">
    <limit lower="-3.140000" upper="3.140000" effort="0.000000" velocity="0.000000"/>
    <origin rpy="-1.570796 0.000000 0.000000" xyz="0.000000 -0.000000 0.104500"/>
    <parent link="art4_3d_link"/>
    <child link="art5_3d_link"/>
    <axis xyz="0.000000 0.000000 1.000000"/>
  </joint>
  <joint name="junta6" type="revolute">
    <limit lower="-3.140000" upper="3.140000" effort="0.000000" velocity="0.000000"/>
    <origin rpy="1.570796 0.000000 0.000000" xyz="0.000000 -0.050000 -0.000000"/>
    <parent link="art5_3d_link"/>
    <child link="art6_3d_link"/>
    <axis xyz="0.000000 0.000000 1.000000"/>
  </joint>
  <link name="Art1_3d_link">
    <collision name="Art1_3d_collision">
      <origin rpy="0.000000 0.000000 0.000000" xyz="0.000000 -0.000000 0.000000"/>
      <geometry>
        <mesh filename="meshes/art1_3d.001.obj" scale="0.001000 0.001000 0.001000"/>
      </geometry>
    </collision>
    <inertial>
      <inertia ixx="0.000013" ixy="-0.000000" ixz="0.000000" iyy="0.000013" iyz="0.000000" izz="0.000010"/>
      <origin rpy="0.000000 0.000000 0.000000" xyz="-0.000001 -0.000000 0.061834"/>
      <mass value="0.001000"/>
    </inertial>
    <visual name="Art1_3d">
      <origin rpy="0.000000 0.000000 0.000000" xyz="0.000000 -0.000000 0.000000"/>
      <geometry>
        <mesh filename="meshes/art1_3d.001.obj" scale="0.001000 0.001000 0.001000"/>
      </geometry>
    </visual>
  </link>
  <link name="art2_3d_link">
    <collision name="art2_3d_collision">
      <origin rpy="1.570796 0.000000 0.000000" xyz="0.000000 0.000000 -0.000000"/>
      <geometry>
        <mesh filename="meshes/art2_3d.001.obj" scale="1.000000 1.000000 1.000000"/>
      </geometry>
    </collision>
    <inertial>
      <inertia ixx="0.000015" ixy="0.000000" ixz="0.000000" iyy="0.000013" iyz="-0.000000" izz="0.000010"/>
      <origin rpy="0.000000 0.000000 0.000000" xyz="-0.000000 -0.080000 -0.000000"/>
      <mass value="0.001000"/>
    </inertial>
    <visual name="art2_3d">
      <origin rpy="1.570796 0.000000 0.000000" xyz="0.000000 0.000000 -0.000000"/>
      <geometry>
        <mesh filename="meshes/art2_3d.001.obj" scale="1.000000 1.000000 1.000000"/>
      </geometry>
    </visual>
  </link>
  <link name="art3_3d_link">
    <collision name="art3_3d_collision">
      <origin rpy="1.570796 0.000000 0.000000" xyz="0.000000 0.000000 0.000000"/>
      <geometry>
        <mesh filename="meshes/art3_3d.001.obj" scale="1.000000 1.000000 1.000000"/>
      </geometry>
    </collision>
    <inertial>
      <inertia ixx="0.000013" ixy="0.000000" ixz="0.000000" iyy="0.000013" iyz="-0.000000" izz="0.000010"/>
      <origin rpy="0.000000 0.000000 0.000000" xyz="0.000000 -0.021415 -0.000001"/>
      <mass value="0.001000"/>
    </inertial>
    <visual name="art3_3d">
      <origin rpy="1.570796 0.000000 0.000000" xyz="0.000000 0.000000 0.000000"/>
      <geometry>
        <mesh filename="meshes/art3_3d.001.obj" scale="1.000000 1.000000 1.000000"/>
      </geometry>
    </visual>
  </link>
  <link name="art4_3d_link">
    <collision name="art4_3d_collision">
      <origin rpy="0.000000 0.000000 0.000000" xyz="0.000000 -0.000000 0.000000"/>
      <geometry>
        <mesh filename="meshes/art4_3d.001.obj" scale="1.000000 1.000000 1.000000"/>
      </geometry>
    </collision>
    <inertial>
      <inertia ixx="0.000013" ixy="0.000000" ixz="0.000000" iyy="0.000013" iyz="-0.000000" izz="0.000010"/>
      <origin rpy="0.000000 0.000000 0.000000" xyz="-0.000000 -0.000000 0.060781"/>
      <mass value="0.001000"/>
    </inertial>
    <visual name="art4_3d">
      <origin rpy="0.000000 0.000000 0.000000" xyz="0.000000 -0.000000 0.000000"/>
      <geometry>
        <mesh filename="meshes/art4_3d.001.obj" scale="1.000000 1.000000 1.000000"/>
      </geometry>
    </visual>
  </link>
  <link name="art5_3d_link">
    <collision name="art5_3d_collision">
      <origin rpy="1.570796 0.000000 0.000000" xyz="0.000000 0.000000 0.000000"/>
      <geometry>
        <mesh filename="meshes/art5_3d.001.obj" scale="1.000000 1.000000 1.000000"/>
      </geometry>
    </collision>
    <inertial>
      <inertia ixx="0.000010" ixy="0.000000" ixz="0.000000" iyy="0.000011" iyz="-0.000000" izz="0.000010"/>
      <origin rpy="0.000000 0.000000 0.000000" xyz="-0.000000 -0.000568 0.000000"/>
      <mass value="0.001000"/>
    </inertial>
    <visual name="art5_3d">
      <origin rpy="1.570796 0.000000 0.000000" xyz="0.000000 0.000000 0.000000"/>
      <geometry>
        <mesh filename="meshes/art5_3d.001.obj" scale="1.000000 1.000000 1.000000"/>
      </geometry>
    </visual>
  </link>
  <link name="art6_3d_link">
    <collision name="art6_3d_collision">
      <origin rpy="0.000000 0.000000 0.000000" xyz="0.000000 0.000000 0.000000"/>
      <geometry>
        <mesh filename="meshes/art6_3d.001.obj" scale="1.000000 1.000000 1.000000"/>
      </geometry>
    </collision>
    <inertial>
      <inertia ixx="0.000010" ixy="0.000000" ixz="0.000000" iyy="0.000010" iyz="0.000000" izz="0.000010"/>
      <origin rpy="0.000000 0.000000 0.000000" xyz="0.000000 0.000000 0.006918"/>
      <mass value="0.001000"/>
    </inertial>
    <visual name="art6_3d">
      <origin rpy="0.000000 0.000000 0.000000" xyz="0.000000 0.000000 0.000000"/>
      <geometry>
        <mesh filename="meshes/art6_3d.001.obj" scale="1.000000 1.000000 1.000000"/>
      </geometry>
    </visual>
  </link>
  <link name="base.000">
    <collision name="base_collision">
      <origin rpy="0.000000 0.000000 0.000000" xyz="0.000000 0.000000 0.000000"/>
      <geometry>
        <mesh filename="meshes/base.001.obj" scale="1.000000 1.000000 1.000000"/>
      </geometry>
    </collision>
    <inertial>
      <inertia ixx="0.000010" ixy="0.000000" ixz="-0.000001" iyy="0.000019" iyz="0.000000" izz="0.000019"/>
      <origin rpy="0.000000 0.000000 0.000000" xyz="0.071677 0.000004 0.045401"/>
      <mass value="0.001000"/>
    </inertial>
    <visual name="base">
      <origin rpy="0.000000 0.000000 0.000000" xyz="0.000000 0.000000 0.000000"/>
      <geometry>
        <mesh filename="meshes/base.001.obj" scale="1.000000 1.000000 1.000000"/>
      </geometry>
    </visual>
  </link>
</robot>